Workbook
Name Slicer_AgeGroup: #N/A
Name Slicer_BusinessTravel: #N/A
Name Slicer_Department: #N/A
Name Slicer_Gender: #N/A
Name Slicer_JobRole: #N/A
Name Slicer_MaritalStatus: #N/A
Name Slicer_OverTime: #N/A
Name Slicer_promotion_status: #N/A

Sheet WA_Fn-UseC_-HR-Employee-Attriti
A1: Age | B1: Attrition | C1: BusinessTravel | D1: DailyRate | E1: Department | F1: DistanceFromHome | G1: Distance_Name | H1: Education | I1: Edu_Name | J1: EducationField | K1: EmployeeCount | L1: EmployeeNumber | M1: EnvironmentSatisfaction | N1: Env_Satis_Name | O1: Gender | P1: HourlyRate | Q1: JobInvolvement | R1: Job_Inv_Name | S1: JobLevel | T1: LevelName | U1: JobRole | V1: JobSatisfaction | W1: Job_Satis_Name | X1: MaritalStatus | Y1: MonthlyIncome | Z1: Income Category | AA1: MonthlyRate | AB1: NumCompaniesWorked | AC1: Over18 | AD1: OverTime | AE1: PercentSalaryHike | AF1: PerformanceRating | AG1: Perform_Rate_Name | AH1: RelationshipSatisfaction | AI1: Rela_Satis_Name | AJ1: StandardHours | AK1: StockOptionLevel | AL1: Stk_opt_lvl_Name | AM1: TotalWorkingYears | AN1: Work_Exp_group | AO1: TrainingTimesLastYear | AP1: WorkLifeBalance | AQ1: wlb_Name | AR1: YearsAtCompany | AS1: emp_loyalty | AT1: YearsInCurrentRole | AU1: YearsSinceLastPromotion | AV1: promotion_status | AW1: YearsWithCurrManager | AX1: Duplicate_flag | AY1: blank_flag_all | AZ1: proper_marital_status | BA1: confirm | BB1: proper_jobrole | BC1: confirm2 | BD1: proper_educationfield | BE1: confirm3 | BF1: proper_department | BG1: confirm4 | BH1: proper_businesstravel | BI1: confirm5 | BJ1: trim_unique_Busstravel | BK1: Distance_from_home | BL1: trim_unique_department | BM1: trim_unique_edufield | BN1: trim_unique_jobrole | BO1: trim_unique_maritelstatus | BP1: trim_unique_attrition | BQ1: Mini_age | BR1: AgeGroup | BS1: Min_Max_income | BT1: Minmax_Work_Exp | BU1: uniq_Promotion | BV1: Years_at_company | BW1: Minmax_Loyalty | BX1: isnum_AtoU_flag | BY1: isneg_AtoU_flag | BZ1: isneg_XtoAI_flag | CA1: Attrition_Yes | CB1: Overtime_yes
A2: 41 | B2: Yes | C2: Travel_Rarely | D2: 1102 | E2: Sales | F2: 1 | G2: {=_xlfn.IFS( F2 <= 10, "Near", F2 <= 20, "Far", TRUE, "Very Far")} -> Near | H2: 2 | I2: =_xlfn.XLOOKUP(H2,Lookup!C:C,Lookup!D:D) -> College | J2: Life Sciences | K2: 1 | L2: 1 | M2: 2 | N2: =_xlfn.XLOOKUP(M2,Lookup!E:E,Lookup!F:F) -> Medium | O2: Female | P2: 94 | Q2: 3 | R2: =_xlfn.XLOOKUP(Q2,Lookup!G:G,Lookup!H:H) -> High | S2: 2 | T2: =_xlfn.XLOOKUP(S2,Lookup!A:A,Lookup!B:B) -> Junior | U2: Sales Executive | V2: 4 | W2: =_xlfn.XLOOKUP(V2,Lookup!I:I,Lookup!J:J) -> Very High | X2: Single | Y2: 5993 | Z2: {=_xlfn.IFS(Y2<3000,"Low",Y2<7000,"Medium",TRUE,"High")} -> Medium | AA2: 19479 | AB2: 8 | AC2: Y | AD2: Yes | AE2: 11 | AF2: 3 | AG2: =_xlfn.XLOOKUP(AF2,Lookup!K:K,Lookup!L:L) -> Meet Expect | AH2: 1 | AI2: =LOOKUP(AH2,Lookup!M:M,Lookup!N:N) -> Low | AJ2: 80 | AK2: 0 | AL2: =_xlfn.XLOOKUP(AK2,Lookup!O:O,Lookup!P:P) -> None | AM2: 8 | AN2: {=_xlfn.IFS( AM2<=5,"0-5", AM2<=10,"6-10", AM2<=20,"11-20", TRUE,"20+")} -> 6-10 | AO2: 0 | AP2: 1 | AQ2: =_xlfn.XLOOKUP(AP2,Lookup!Q:Q,Lookup!R:R) -> Bad | AR2: 6 | AS2: {=_xlfn.IFS( AR2 <=1,"New Employee", AR2 <=3, "Early Career", AR2 <=7, "Experienced", TRUE, "Veteran")} -> Experienced | AT2: 4 | AU2: 0 | AV2: {=_xlfn.IFS( AU2=0,"Recently Promoted", AU2<=3, "Normal", TRUE, "Long Time No Promotion")} -> Recently Promoted | AW2: 5 | AX2: =IF(COUNTIF(L2:$L$1471,L2)>1,1,0) -> 0 | AY2: =COUNTBLANK(A2:AW1471) -> 0 | AZ2: {=PROPER(X2:X1471)} -> #VALUE! | BA2: =IF(AZ2=X2,1,0) -> #VALUE! | BB2: {=PROPER(U2:U1471)} -> #VALUE! | BC2: =IF(U2=BB2,1,0) -> #VALUE! | BD2: {=PROPER(J2:J1471)} -> #VALUE! | BE2: =IF(BD2=J2,1,0) -> #VALUE! | BF2: {=PROPER(E2:E1471)} -> #VALUE! | BG2: =IF(BF2=E2,1,0) -> #VALUE! | BH2: {=PROPER(C2:C1471)} -> #VALUE! | BI2: =IF(C2=BH2,1,0) -> #VALUE! | BJ2: {=_xlfn.UNIQUE(_xlfn.ANCHORARRAY(BH2))} -> #VALUE! | BK2: =MIN(F2:F1471) -> 1 | BL2: {=_xlfn.UNIQUE(_xlfn.ANCHORARRAY(BF2))} -> #VALUE! | BM2: {=_xlfn.UNIQUE(_xlfn.ANCHORARRAY(BD2))} -> #VALUE! | BN2: {=_xlfn.UNIQUE(_xlfn.ANCHORARRAY(BB2))} -> #VALUE! | BO2: {=_xlfn.UNIQUE(_xlfn.ANCHORARRAY(AZ2))} -> #VALUE! | BP2: {=_xlfn.UNIQUE(B2:B1471)} -> #VALUE! | BQ2: =MIN(A2:A1471) -> 18 | BR2: {=_xlfn.IFS( A2<=25,"18-25", A2<=35,"26-35", A2<=45,"36-45", A2<=59,"46-59", TRUE,"60+")} -> 36-45 | BS2: =MIN(Y2:Y1471) -> 1009 | BT2: =MIN(AM2:AM1471) -> 0 | BU2: {=_xlfn.UNIQUE(AU2:AU1471)} -> #VALUE! | BV2: {=_xlfn.UNIQUE(AR2:AR1471)} -> #VALUE! | BW2: =MIN(_xlfn.ANCHORARRAY(BV2)) -> #VALUE! | BX2: =AND(ISNUMBER(A2),ISNUMBER(D2),ISNUMBER(A2),ISNUMBER(F2),ISNUMBER(H2),ISNUMBER(K2),ISNUMBER(L2),ISNUMBER(M2),ISNUMBER(P2),ISNUMBER(Q2),ISNUMBER(S2),ISNUMBER(V2),ISNUMBER(Y2),ISNUMBER(AA2),ISNUMBER(AB2)) -> TRUE | BY2: =AND(ISNUMBER(A2),ISNUMBER(D2),ISNUMBER(A2),ISNUMBER(F2),ISNUMBER(H2),ISNUMBER(K2),ISNUMBER(L2),ISNUMBER(M2),ISNUMBER(P2),ISNUMBER(Q2),ISNUMBER(S2),ISNUMBER(V2),ISNUMBER(Y2),ISNUMBER(AA2),ISNUMBER(AB2))>0 -> TRUE | BZ2: =COUNT(AE2:AW2)>0 -> TRUE | CA2: =IF(tblemployee[[#This Row],[Attrition]]="Yes",1,0) -> 1 | CB2: =IF(tblemployee[[#This Row],[OverTime]]="Yes",1,0) -> 1
A3: 49 | B3: No | C3: Travel_Frequently | D3: 279 | E3: Research & Development | F3: 8 | G3: {=_xlfn.IFS( F3 <= 10, "Near", F3 <= 20, "Far", TRUE, "Very Far")} -> Near | H3: 1 | I3: =_xlfn.XLOOKUP(H3,Lookup!C:C,Lookup!D:D) -> Below College | J3: Life Sciences | K3: 1 | L3: 2 | M3: 3 | N3: =_xlfn.XLOOKUP(M3,Lookup!E:E,Lookup!F:F) -> High | O3: Male | P3: 61 | Q3: 2 | R3: =_xlfn.XLOOKUP(Q3,Lookup!G:G,Lookup!H:H) -> Medium | S3: 2 | T3: =_xlfn.XLOOKUP(S3,Lookup!A:A,Lookup!B:B) -> Junior | U3: Research Scientist | V3: 2 | W3: =_xlfn.XLOOKUP(V3,Lookup!I:I,Lookup!J:J) -> Medium | X3: Married | Y3: 5130 | Z3: {=_xlfn.IFS(Y3<3000,"Low",Y3<7000,"Medium",TRUE,"High")} -> Medium | AA3: 24907 | AB3: 1 | AC3: Y | AD3: No | AE3: 23 | AF3: 4 | AG3: =_xlfn.XLOOKUP(AF3,Lookup!K:K,Lookup!L:L) -> Exceed Expect | AH3: 4 | AI3: =LOOKUP(AH3,Lookup!M:M,Lookup!N:N) -> Very High | AJ3: 80 | AK3: 1 | AL3: =_xlfn.XLOOKUP(AK3,Lookup!O:O,Lookup!P:P) -> Basic | AM3: 10 | AN3: {=_xlfn.IFS( AM3<=5,"0-5", AM3<=10,"6-10", AM3<=20,"11-20", TRUE,"20+")} -> 6-10 | AO3: 3 | AP3: 3 | AQ3: =_xlfn.XLOOKUP(AP3,Lookup!Q:Q,Lookup!R:R) -> Better | AR3: 10 | AS3: {=_xlfn.IFS( AR3 <=1,"New Employee", AR3 <=3, "Early Career", AR3 <=7, "Experienced", TRUE, "Veteran")} -> Veteran | AT3: 7 | AU3: 1 | AV3: {=_xlfn.IFS( AU3=0,"Recently Promoted", AU3<=3, "Normal", TRUE, "Long Time No Promotion")} -> Normal | AW3: 7 | AX3: =IF(COUNTIF(L3:$L$1471,L3)>1,1,0) -> 0 | BA3: =IF(AZ3=X3,1,0) -> 0 | BC3: =IF(U3=BB3,1,0) -> 0 | BE3: =IF(BD3=J3,1,0) -> 0 | BG3: =IF(BF3=E3,1,0) -> 0 | BI3: =IF(C3=BH3,1,0) -> 0 | BK3: =MAX(F2:F1471) -> 29 | BQ3: =MAX(A2:A1471) -> 60 | BR3: {=_xlfn.IFS( A3<=25,"18-25", A3<=35,"26-35", A3<=45,"36-45", A3<=59,"46-59", TRUE,"60+")} -> 46-59 | BS3: =MAX(Y2:Y1471) -> 19999 | BT3: =MAX(AM2:AM1471) -> 40 | BW3: =MAX(_xlfn.ANCHORARRAY(BV2)) -> #VALUE! | BX3: =AND(ISNUMBER(A3),ISNUMBER(D3),ISNUMBER(A3),ISNUMBER(F3),ISNUMBER(H3),ISNUMBER(K3),ISNUMBER(L3),ISNUMBER(M3),ISNUMBER(P3),ISNUMBER(Q3),ISNUMBER(S3),ISNUMBER(V3),ISNUMBER(Y3),ISNUMBER(AA3),ISNUMBER(AB3)) -> TRUE | BY3: =AND(ISNUMBER(A3),ISNUMBER(D3),ISNUMBER(A3),ISNUMBER(F3),ISNUMBER(H3),ISNUMBER(K3),ISNUMBER(L3),ISNUMBER(M3),ISNUMBER(P3),ISNUMBER(Q3),ISNUMBER(S3),ISNUMBER(V3),ISNUMBER(Y3),ISNUMBER(AA3),ISNUMBER(AB3))>0 -> TRUE | BZ3: =COUNT(AE3:AW3)>0 -> TRUE | CA3: =IF(tblemployee[[#This Row],[Attrition]]="Yes",1,0) -> 0 | CB3: =IF(tblemployee[[#This Row],[OverTime]]="Yes",1,0) -> 0
A4: 37 | B4: Yes | C4: Travel_Rarely | D4: 1373 | E4: Research & Development | F4: 2 | G4: {=_xlfn.IFS( F4 <= 10, "Near", F4 <= 20, "Far", TRUE, "Very Far")} -> Near | H4: 2 | I4: =_xlfn.XLOOKUP(H4,Lookup!C:C,Lookup!D:D) -> College | J4: Other | K4: 1 | L4: 4 | M4: 4 | N4: =_xlfn.XLOOKUP(M4,Lookup!E:E,Lookup!F:F) -> Very High | O4: Male | P4: 92 | Q4: 2 | R4: =_xlfn.XLOOKUP(Q4,Lookup!G:G,Lookup!H:H) -> Medium | S4: 1 | T4: =_xlfn.XLOOKUP(S4,Lookup!A:A,Lookup!B:B) -> Entry Level | U4: Laboratory Technician | V4: 3 | W4: =_xlfn.XLOOKUP(V4,Lookup!I:I,Lookup!J:J) -> High | X4: Single | Y4: 2090 | Z4: {=_xlfn.IFS(Y4<3000,"Low",Y4<7000,"Medium",TRUE,"High")} -> Low | AA4: 2396 | AB4: 6 | AC4: Y | AD4: Yes | AE4: 15 | AF4: 3 | AG4: =_xlfn.XLOOKUP(AF4,Lookup!K:K,Lookup!L:L) -> Meet Expect | AH4: 2 | AI4: =LOOKUP(AH4,Lookup!M:M,Lookup!N:N) -> Medium | AJ4: 80 | AK4: 0 | AL4: =_xlfn.XLOOKUP(AK4,Lookup!O:O,Lookup!P:P) -> None | AM4: 7 | AN4: {=_xlfn.IFS( AM4<=5,"0-5", AM4<=10,"6-10", AM4<=20,"11-20", TRUE,"20+")} -> 6-10 | AO4: 3 | AP4: 3 | AQ4: =_xlfn.XLOOKUP(AP4,Lookup!Q:Q,Lookup!R:R) -> Better | AR4: 0 | AS4: {=_xlfn.IFS( AR4 <=1,"New Employee", AR4 <=3, "Early Career", AR4 <=7, "Experienced", TRUE, "Veteran")} -> New Employee | AT4: 0 | AU4: 0 | AV4: {=_xlfn.IFS( AU4=0,"Recently Promoted", AU4<=3, "Normal", TRUE, "Long Time No Promotion")} -> Recently Promoted | AW4: 0 | AX4: =IF(COUNTIF(L4:$L$1471,L4)>1,1,0) -> 0 | BA4: =IF(AZ4=X4,1,0) -> 0 | BC4: =IF(U4=BB4,1,0) -> 0 | BE4: =IF(BD4=J4,1,0) -> 0 | BG4: =IF(BF4=E4,1,0) -> 0 | BI4: =IF(C4=BH4,1,0) -> 0 | BR4: {=_xlfn.IFS( A4<=25,"18-25", A4<=35,"26-35", A4<=45,"36-45", A4<=59,"46-59", TRUE,"60+")} -> 36-45 | BX4: =AND(ISNUMBER(A4),ISNUMBER(D4),ISNUMBER(A4),ISNUMBER(F4),ISNUMBER(H4),ISNUMBER(K4),ISNUMBER(L4),ISNUMBER(M4),ISNUMBER(P4),ISNUMBER(Q4),ISNUMBER(S4),ISNUMBER(V4),ISNUMBER(Y4),ISNUMBER(AA4),ISNUMBER(AB4)) -> TRUE | BY4: =AND(ISNUMBER(A4),ISNUMBER(D4),ISNUMBER(A4),ISNUMBER(F4),ISNUMBER(H4),ISNUMBER(K4),ISNUMBER(L4),ISNUMBER(M4),ISNUMBER(P4),ISNUMBER(Q4),ISNUMBER(S4),ISNUMBER(V4),ISNUMBER(Y4),ISNUMBER(AA4),ISNUMBER(AB4))>0 -> TRUE | BZ4: =COUNT(AE4:AW4)>0 -> TRUE | CA4: =IF(tblemployee[[#This Row],[Attrition]]="Yes",1,0) -> 1 | CB4: =IF(tblemployee[[#This Row],[OverTime]]="Yes",1,0) -> 1
A5: 33 | B5: No | C5: Travel_Frequently | D5: 1392 | E5: Research & Development | F5: 3 | G5: {=_xlfn.IFS( F5 <= 10, "Near", F5 <= 20, "Far", TRUE, "Very Far")} -> Near | H5: 4 | I5: =_xlfn.XLOOKUP(H5,Lookup!C:C,Lookup!D:D) -> Master | J5: Life Sciences | K5: 1 | L5: 5 | M5: 4 | N5: =_xlfn.XLOOKUP(M5,Lookup!E:E,Lookup!F:F) -> Very High | O5: Female | P5: 56 | Q5: 3 | R5: =_xlfn.XLOOKUP(Q5,Lookup!G:G,Lookup!H:H) -> High | S5: 1 | T5: =_xlfn.XLOOKUP(S5,Lookup!A:A,Lookup!B:B) -> Entry Level | U5: Research Scientist | V5: 3 | W5: =_xlfn.XLOOKUP(V5,Lookup!I:I,Lookup!J:J) -> High | X5: Married | Y5: 2909 | Z5: {=_xlfn.IFS(Y5<3000,"Low",Y5<7000,"Medium",TRUE,"High")} -> Low | AA5: 23159 | AB5: 1 | AC5: Y | AD5: Yes | AE5: 11 | AF5: 3 | AG5: =_xlfn.XLOOKUP(AF5,Lookup!K:K,Lookup!L:L) -> Meet Expect | AH5: 3 | AI5: =LOOKUP(AH5,Lookup!M:M,Lookup!N:N) -> High | AJ5: 80 | AK5: 0 | AL5: =_xlfn.XLOOKUP(AK5,Lookup!O:O,Lookup!P:P) -> None | AM5: 8 | AN5: {=_xlfn.IFS( AM5<=5,"0-5", AM5<=10,"6-10", AM5<=20,"11-20", TRUE,"20+")} -> 6-10 | AO5: 3 | AP5: 3 | AQ5: =_xlfn.XLOOKUP(AP5,Lookup!Q:Q,Lookup!R:R) -> Better | AR5: 8 | AS5: {=_xlfn.IFS( AR5 <=1,"New Employee", AR5 <=3, "Early Career", AR5 <=7, "Experienced", TRUE, "Veteran")} -> Veteran | AT5: 7 | AU5: 3 | AV5: {=_xlfn.IFS( AU5=0,"Recently Promoted", AU5<=3, "Normal", TRUE, "Long Time No Promotion")} -> Normal | AW5: 0 | AX5: =IF(COUNTIF(L5:$L$1471,L5)>1,1,0) -> 0 | BA5: =IF(AZ5=X5,1,0) -> 0 | BC5: =IF(U5=BB5,1,0) -> 0 | BE5: =IF(BD5=J5,1,0) -> 0 | BG5: =IF(BF5=E5,1,0) -> 0 | BI5: =IF(C5=BH5,1,0) -> 0 | BR5: {=_xlfn.IFS( A5<=25,"18-25", A5<=35,"26-35", A5<=45,"36-45", A5<=59,"46-59", TRUE,"60+")} -> 26-35 | BX5: =AND(ISNUMBER(A5),ISNUMBER(D5),ISNUMBER(A5),ISNUMBER(F5),ISNUMBER(H5),ISNUMBER(K5),ISNUMBER(L5),ISNUMBER(M5),ISNUMBER(P5),ISNUMBER(Q5),ISNUMBER(S5),ISNUMBER(V5),ISNUMBER(Y5),ISNUMBER(AA5),ISNUMBER(AB5)) -> TRUE | BY5: =AND(ISNUMBER(A5),ISNUMBER(D5),ISNUMBER(A5),ISNUMBER(F5),ISNUMBER(H5),ISNUMBER(K5),ISNUMBER(L5),ISNUMBER(M5),ISNUMBER(P5),ISNUMBER(Q5),ISNUMBER(S5),ISNUMBER(V5),ISNUMBER(Y5),ISNUMBER(AA5),ISNUMBER(AB5))>0 -> TRUE | BZ5: =COUNT(AE5:AW5)>0 -> TRUE | CA5: =IF(tblemployee[[#This Row],[Attrition]]="Yes",1,0) -> 0 | CB5: =IF(tblemployee[[#This Row],[OverTime]]="Yes",1,0) -> 1
A6: 27 | B6: No | C6: Travel_Rarely | D6: 591 | E6: Research & Development | F6: 2 | G6: {=_xlfn.IFS( F6 <= 10, "Near", F6 <= 20, "Far", TRUE, "Very Far")} -> Near | H6: 1 | I6: =_xlfn.XLOOKUP(H6,Lookup!C:C,Lookup!D:D) -> Below College | J6: Medical | K6: 1 | L6: 7 | M6: 1 | N6: =_xlfn.XLOOKUP(M6,Lookup!E:E,Lookup!F:F) -> Low | O6: Male | P6: 40 | Q6: 3 | R6: =_xlfn.XLOOKUP(Q6,Lookup!G:G,Lookup!H:H) -> High | S6: 1 | T6: =_xlfn.XLOOKUP(S6,Lookup!A:A,Lookup!B:B) -> Entry Level | U6: Laboratory Technician | V6: 2 | W6: =_xlfn.XLOOKUP(V6,Lookup!I:I,Lookup!J:J) -> Medium | X6: Married | Y6: 3468 | Z6: {=_xlfn.IFS(Y6<3000,"Low",Y6<7000,"Medium",TRUE,"High")} -> Medium | AA6: 16632 | AB6: 9 | AC6: Y | AD6: No | AE6: 12 | AF6: 3 | AG6: =_xlfn.XLOOKUP(AF6,Lookup!K:K,Lookup!L:L) -> Meet Expect | AH6: 4 | AI6: =LOOKUP(AH6,Lookup!M:M,Lookup!N:N) -> Very High | AJ6: 80 | AK6: 1 | AL6: =_xlfn.XLOOKUP(AK6,Lookup!O:O,Lookup!P:P) -> Basic | AM6: 6 | AN6: {=_xlfn.IFS( AM6<=5,"0-5", AM6<=10,"6-10", AM6<=20,"11-20", TRUE,"20+")} -> 6-10 | AO6: 3 | AP6: 3 | AQ6: =_xlfn.XLOOKUP(AP6,Lookup!Q:Q,Lookup!R:R) -> Better | AR6: 2 | AS6: {=_xlfn.IFS( AR6 <=1,"New Employee", AR6 <=3, "Early Career", AR6 <=7, "Experienced", TRUE, "Veteran")} -> Early Career | AT6: 2 | AU6: 2 | AV6: {=_xlfn.IFS( AU6=0,"Recently Promoted", AU6<=3, "Normal", TRUE, "Long Time No Promotion")} -> Normal | AW6: 2 | AX6: =IF(COUNTIF(L6:$L$1471,L6)>1,1,0) -> 0 | BA6: =IF(AZ6=X6,1,0) -> 0 | BC6: =IF(U6=BB6,1,0) -> 0 | BE6: =IF(BD6=J6,1,0) -> 0 | BG6: =IF(BF6=E6,1,0) -> 0 | BI6: =IF(C6=BH6,1,0) -> 0 | BR6: {=_xlfn.IFS( A6<=25,"18-25", A6<=35,"26-35", A6<=45,"36-45", A6<=59,"46-59", TRUE,"60+")} -> 26-35 | BX6: =AND(ISNUMBER(A6),ISNUMBER(D6),ISNUMBER(A6),ISNUMBER(F6),ISNUMBER(H6),ISNUMBER(K6),ISNUMBER(L6),ISNUMBER(M6),ISNUMBER(P6),ISNUMBER(Q6),ISNUMBER(S6),ISNUMBER(V6),ISNUMBER(Y6),ISNUMBER(AA6),ISNUMBER(AB6)) -> TRUE | BY6: =AND(ISNUMBER(A6),ISNUMBER(D6),ISNUMBER(A6),ISNUMBER(F6),ISNUMBER(H6),ISNUMBER(K6),ISNUMBER(L6),ISNUMBER(M6),ISNUMBER(P6),ISNUMBER(Q6),ISNUMBER(S6),ISNUMBER(V6),ISNUMBER(Y6),ISNUMBER(AA6),ISNUMBER(AB6))>0 -> TRUE | BZ6: =COUNT(AE6:AW6)>0 -> TRUE | CA6: =IF(tblemployee[[#This Row],[Attrition]]="Yes",1,0) -> 0 | CB6: =IF(tblemployee[[#This Row],[OverTime]]="Yes",1,0) -> 0
A7: 32 | B7: No | C7: Travel_Frequently | D7: 1005 | E7: Research & Development | F7: 2 | G7: {=_xlfn.IFS( F7 <= 10, "Near", F7 <= 20, "Far", TRUE, "Very Far")} -> Near | H7: 2 | I7: =_xlfn.XLOOKUP(H7,Lookup!C:C,Lookup!D:D) -> College | J7: Life Sciences | K7: 1 | L7: 8 | M7: 4 | N7: =_xlfn.XLOOKUP(M7,Lookup!E:E,Lookup!F:F) -> Very High | O7: Male | P7: 79 | Q7: 3 | R7: =_xlfn.XLOOKUP(Q7,Lookup!G:G,Lookup!H:H) -> High | S7: 1 | T7: =_xlfn.XLOOKUP(S7,Lookup!A:A,Lookup!B:B) -> Entry Level | U7: Laboratory Technician | V7: 4 | W7: =_xlfn.XLOOKUP(V7,Lookup!I:I,Lookup!J:J) -> Very High | X7: Single | Y7: 3068 | Z7: {=_xlfn.IFS(Y7<3000,"Low",Y7<7000,"Medium",TRUE,"High")} -> Medium | AA7: 11864 | AB7: 0 | AC7: Y | AD7: No | AE7: 13 | AF7: 3 | AG7: =_xlfn.XLOOKUP(AF7,Lookup!K:K,Lookup!L:L) -> Meet Expect | AH7: 3 | AI7: =LOOKUP(AH7,Lookup!M:M,Lookup!N:N) -> High | AJ7: 80 | AK7: 0 | AL7: =_xlfn.XLOOKUP(AK7,Lookup!O:O,Lookup!P:P) -> None | AM7: 8 | AN7: {=_xlfn.IFS( AM7<=5,"0-5", AM7<=10,"6-10", AM7<=20,"11-20", TRUE,"20+")} -> 6-10 | AO7: 2 | AP7: 2 | AQ7: =_xlfn.XLOOKUP(AP7,Lookup!Q:Q,Lookup!R:R) -> Good | AR7: 7 | AS7: {=_xlfn.IFS( AR7 <=1,"New Employee", AR7 <=3, "Early Career", AR7 <=7, "Experienced", TRUE, "Veteran")} -> Experienced | AT7: 7 | AU7: 3 | AV7: {=_xlfn.IFS( AU7=0,"Recently Promoted", AU7<=3, "Normal", TRUE, "Long Time No Promotion")} -> Normal | AW7: 6 | AX7: =IF(COUNTIF(L7:$L$1471,L7)>1,1,0) -> 0 | BA7: =IF(AZ7=X7,1,0) -> 0 | BC7: =IF(U7=BB7,1,0) -> 0 | BE7: =IF(BD7=J7,1,0) -> 0 | BG7: =IF(BF7=E7,1,0) -> 0 | BI7: =IF(C7=BH7,1,0) -> 0 | BR7: {=_xlfn.IFS( A7<=25,"18-25", A7<=35,"26-35", A7<=45,"36-45", A7<=59,"46-59", TRUE,"60+")} -> 26-35 | BX7: =AND(ISNUMBER(A7),ISNUMBER(D7),ISNUMBER(A7),ISNUMBER(F7),ISNUMBER(H7),ISNUMBER(K7),ISNUMBER(L7),ISNUMBER(M7),ISNUMBER(P7),ISNUMBER(Q7),ISNUMBER(S7),ISNUMBER(V7),ISNUMBER(Y7),ISNUMBER(AA7),ISNUMBER(AB7)) -> TRUE | BY7: =AND(ISNUMBER(A7),ISNUMBER(D7),ISNUMBER(A7),ISNUMBER(F7),ISNUMBER(H7),ISNUMBER(K7),ISNUMBER(L7),ISNUMBER(M7),ISNUMBER(P7),ISNUMBER(Q7),ISNUMBER(S7),ISNUMBER(V7),ISNUMBER(Y7),ISNUMBER(AA7),ISNUMBER(AB7))>0 -> TRUE | BZ7: =COUNT(AE7:AW7)>0 -> TRUE | CA7: =IF(tblemployee[[#This Row],[Attrition]]="Yes",1,0) -> 0 | CB7: =IF(tblemployee[[#This Row],[OverTime]]="Yes",1,0) -> 0
A8: 59 | B8: No | C8: Travel_Rarely | D8: 1324 | E8: Research & Development | F8: 3 | G8: {=_xlfn.IFS( F8 <= 10, "Near", F8 <= 20, "Far", TRUE, "Very Far")} -> Near | H8: 3 | I8: =_xlfn.XLOOKUP(H8,Lookup!C:C,Lookup!D:D) -> Bachelor | J8: Medical | K8: 1 | L8: 10 | M8: 3 | N8: =_xlfn.XLOOKUP(M8,Lookup!E:E,Lookup!F:F) -> High | O8: Female | P8: 81 | Q8: 4 | R8: =_xlfn.XLOOKUP(Q8,Lookup!G:G,Lookup!H:H) -> Very High | S8: 1 | T8: =_xlfn.XLOOKUP(S8,Lookup!A:A,Lookup!B:B) -> Entry Level | U8: Laboratory Technician | V8: 1 | W8: =_xlfn.XLOOKUP(V8,Lookup!I:I,Lookup!J:J) -> Low | X8: Married | Y8: 2670 | Z8: {=_xlfn.IFS(Y8<3000,"Low",Y8<7000,"Medium",TRUE,"High")} -> Low | AA8: 9964 | AB8: 4 | AC8: Y | AD8: Yes | AE8: 20 | AF8: 4 | AG8: =_xlfn.XLOOKUP(AF8,Lookup!K:K,Lookup!L:L) -> Exceed Expect | AH8: 1 | AI8: =LOOKUP(AH8,Lookup!M:M,Lookup!N:N) -> Low | AJ8: 80 | AK8: 3 | AL8: =_xlfn.XLOOKUP(AK8,Lookup!O:O,Lookup!P:P) -> High | AM8: 12 | AN8: {=_xlfn.IFS( AM8<=5,"0-5", AM8<=10,"6-10", AM8<=20,"11-20", TRUE,"20+")} -> 11-20 | AO8: 3 | AP8: 2 | AQ8: =_xlfn.XLOOKUP(AP8,Lookup!Q:Q,Lookup!R:R) -> Good | AR8: 1 | AS8: {=_xlfn.IFS( AR8 <=1,"New Employee", AR8 <=3, "Early Career", AR8 <=7, "Experienced", TRUE, "Veteran")} -> New Employee | AT8: 0 | AU8: 0 | AV8: {=_xlfn.IFS( AU8=0,"Recently Promoted", AU8<=3, "Normal", TRUE, "Long Time No Promotion")} -> Recently Promoted | AW8: 0 | AX8: =IF(COUNTIF(L8:$L$1471,L8)>1,1,0) -> 0 | BA8: =IF(AZ8=X8,1,0) -> 0 | BC8: =IF(U8=BB8,1,0) -> 0 | BE8: =IF(BD8=J8,1,0) -> 0 | BG8: =IF(BF8=E8,1,0) -> 0 | BI8: =IF(C8=BH8,1,0) -> 0 | BR8: {=_xlfn.IFS( A8<=25,"18-25", A8<=35,"26-35", A8<=45,"36-45", A8<=59,"46-59", TRUE,"60+")} -> 46-59 | BX8: =AND(ISNUMBER(A8),ISNUMBER(D8),ISNUMBER(A8),ISNUMBER(F8),ISNUMBER(H8),ISNUMBER(K8),ISNUMBER(L8),ISNUMBER(M8),ISNUMBER(P8),ISNUMBER(Q8),ISNUMBER(S8),ISNUMBER(V8),ISNUMBER(Y8),ISNUMBER(AA8),ISNUMBER(AB8)) -> TRUE | BY8: =AND(ISNUMBER(A8),ISNUMBER(D8),ISNUMBER(A8),ISNUMBER(F8),ISNUMBER(H8),ISNUMBER(K8),ISNUMBER(L8),ISNUMBER(M8),ISNUMBER(P8),ISNUMBER(Q8),ISNUMBER(S8),ISNUMBER(V8),ISNUMBER(Y8),ISNUMBER(AA8),ISNUMBER(AB8))>0 -> TRUE | BZ8: =COUNT(AE8:AW8)>0 -> TRUE | CA8: =IF(tblemployee[[#This Row],[Attrition]]="Yes",1,0) -> 0 | CB8: =IF(tblemployee[[#This Row],[OverTime]]="Yes",1,0) -> 1
A9: 30 | B9: No | C9: Travel_Rarely | D9: 1358 | E9: Research & Development | F9: 24 | G9: {=_xlfn.IFS( F9 <= 10, "Near", F9 <= 20, "Far", TRUE, "Very Far")} -> Very Far | H9: 1 | I9: =_xlfn.XLOOKUP(H9,Lookup!C:C,Lookup!D:D) -> Below College | J9: Life Sciences | K9: 1 | L9: 11 | M9: 4 | N9: =_xlfn.XLOOKUP(M9,Lookup!E:E,Lookup!F:F) -> Very High | O9: Male | P9: 67 | Q9: 3 | R9: =_xlfn.XLOOKUP(Q9,Lookup!G:G,Lookup!H:H) -> High | S9: 1 | T9: =_xlfn.XLOOKUP(S9,Lookup!A:A,Lookup!B:B) -> Entry Level | U9: Laboratory Technician | V9: 3 | W9: =_xlfn.XLOOKUP(V9,Lookup!I:I,Lookup!J:J) -> High | X9: Divorced | Y9: 2693 | Z9: {=_xlfn.IFS(Y9<3000,"Low",Y9<7000,"Medium",TRUE,"High")} -> Low | AA9: 13335 | AB9: 1 | AC9: Y | AD9: No | AE9: 22 | AF9: 4 | AG9: =_xlfn.XLOOKUP(AF9,Lookup!K:K,Lookup!L:L) -> Exceed Expect | AH9: 2 | AI9: =LOOKUP(AH9,Lookup!M:M,Lookup!N:N) -> Medium | AJ9: 80 | AK9: 1 | AL9: =_xlfn.XLOOKUP(AK9,Lookup!O:O,Lookup!P:P) -> Basic | AM9: 1 | AN9: {=_xlfn.IFS( AM9<=5,"0-5", AM9<=10,"6-10", AM9<=20,"11-20", TRUE,"20+")} -> 0-5 | AO9: 2 | AP9: 3 | AQ9: =_xlfn.XLOOKUP(AP9,Lookup!Q:Q,Lookup!R:R) -> Better | AR9: 1 | AS9: {=_xlfn.IFS( AR9 <=1,"New Employee", AR9 <=3, "Early Career", AR9 <=7, "Experienced", TRUE, "Veteran")} -> New Employee | AT9: 0 | AU9: 0 | AV9: {=_xlfn.IFS( AU9=0,"Recently Promoted", AU9<=3, "Normal", TRUE, "Long Time No Promotion")} -> Recently Promoted | AW9: 0 | AX9: =IF(COUNTIF(L9:$L$1471,L9)>1,1,0) -> 0 | BA9: =IF(AZ9=X9,1,0) -> 0 | BC9: =IF(U9=BB9,1,0) -> 0 | BE9: =IF(BD9=J9,1,0) -> 0 | BG9: =IF(BF9=E9,1,0) -> 0 | BI9: =IF(C9=BH9,1,0) -> 0 | BR9: {=_xlfn.IFS( A9<=25,"18-25", A9<=35,"26-35", A9<=45,"36-45", A9<=59,"46-59", TRUE,"60+")} -> 26-35 | BX9: =AND(ISNUMBER(A9),ISNUMBER(D9),ISNUMBER(A9),ISNUMBER(F9),ISNUMBER(H9),ISNUMBER(K9),ISNUMBER(L9),ISNUMBER(M9),ISNUMBER(P9),ISNUMBER(Q9),ISNUMBER(S9),ISNUMBER(V9),ISNUMBER(Y9),ISNUMBER(AA9),ISNUMBER(AB9)) -> TRUE | BY9: =AND(ISNUMBER(A9),ISNUMBER(D9),ISNUMBER(A9),ISNUMBER(F9),ISNUMBER(H9),ISNUMBER(K9),ISNUMBER(L9),ISNUMBER(M9),ISNUMBER(P9),ISNUMBER(Q9),ISNUMBER(S9),ISNUMBER(V9),ISNUMBER(Y9),ISNUMBER(AA9),ISNUMBER(AB9))>0 -> TRUE | BZ9: =COUNT(AE9:AW9)>0 -> TRUE | CA9: =IF(tblemployee[[#This Row],[Attrition]]="Yes",1,0) -> 0 | CB9: =IF(tblemployee[[#This Row],[OverTime]]="Yes",1,0) -> 0
A10: 38 | B10: No | C10: Travel_Frequently | D10: 216 | E10: Research & Development | F10: 23 | G10: {=_xlfn.IFS( F10 <= 10, "Near", F10 <= 20, "Far", TRUE, "Very Far")} -> Very Far | H10: 3 | I10: =_xlfn.XLOOKUP(H10,Lookup!C:C,Lookup!D:D) -> Bachelor | J10: Life Sciences | K10: 1 | L10: 12 | M10: 4 | N10: =_xlfn.XLOOKUP(M10,Lookup!E:E,Lookup!F:F) -> Very High | O10: Male | P10: 44 | Q10: 2 | R10: =_xlfn.XLOOKUP(Q10,Lookup!G:G,Lookup!H:H) -> Medium | S10: 3 | T10: =_xlfn.XLOOKUP(S10,Lookup!A:A,Lookup!B:B) -> Senior | U10: Manufacturing Director | V10: 3 | W10: =_xlfn.XLOOKUP(V10,Lookup!I:I,Lookup!J:J) -> High | X10: Single | Y10: 9526 | Z10: {=_xlfn.IFS(Y10<3000,"Low",Y10<7000,"Medium",TRUE,"High")} -> High | AA10: 8787 | AB10: 0 | AC10: Y | AD10: No | AE10: 21 | AF10: 4 | AG10: =_xlfn.XLOOKUP(AF10,Lookup!K:K,Lookup!L:L) -> Exceed Expect | AH10: 2 | AI10: =LOOKUP(AH10,Lookup!M:M,Lookup!N:N) -> Medium | AJ10: 80 | AK10: 0 | AL10: =_xlfn.XLOOKUP(AK10,Lookup!O:O,Lookup!P:P) -> None | AM10: 10 | AN10: {=_xlfn.IFS( AM10<=5,"0-5", AM10<=10,"6-10", AM10<=20,"11-20", TRUE,"20+")} -> 6-10 | AO10: 2 | AP10: 3 | AQ10: =_xlfn.XLOOKUP(AP10,Lookup!Q:Q,Lookup!R:R) -> Better | AR10: 9 | AS10: {=_xlfn.IFS( AR10 <=1,"New Employee", AR10 <=3, "Early Career", AR10 <=7, "Experienced", TRUE, "Veteran")} -> Veteran | AT10: 7 | AU10: 1 | AV10: {=_xlfn.IFS( AU10=0,"Recently Promoted", AU10<=3, "Normal", TRUE, "Long Time No Promotion")} -> Normal | AW10: 8 | AX10: =IF(COUNTIF(L10:$L$1471,L10)>1,1,0) -> 0 | BA10: =IF(AZ10=X10,1,0) -> 0 | BC10: =IF(U10=BB10,1,0) -> 0 | BE10: =IF(BD10=J10,1,0) -> 0 | BG10: =IF(BF10=E10,1,0) -> 0 | BI10: =IF(C10=BH10,1,0) -> 0 | BR10: {=_xlfn.IFS( A10<=25,"18-25", A10<=35,"26-35", A10<=45,"36-45", A10<=59,"46-59", TRUE,"60+")} -> 36-45 | BX10: =AND(ISNUMBER(A10),ISNUMBER(D10),ISNUMBER(A10),ISNUMBER(F10),ISNUMBER(H10),ISNUMBER(K10),ISNUMBER(L10),ISNUMBER(M10),ISNUMBER(P10),ISNUMBER(Q10),ISNUMBER(S10),ISNUMBER(V10),ISNUMBER(Y10),ISNUMBER(AA10),ISNUMBER(AB10)) -> TRUE | BY10: =AND(ISNUMBER(A10),ISNUMBER(D10),ISNUMBER(A10),ISNUMBER(F10),ISNUMBER(H10),ISNUMBER(K10),ISNUMBER(L10),ISNUMBER(M10),ISNUMBER(P10),ISNUMBER(Q10),ISNUMBER(S10),ISNUMBER(V10),ISNUMBER(Y10),ISNUMBER(AA10),ISNUMBER(AB10))>0 -> TRUE | BZ10: =COUNT(AE10:AW10)>0 -> TRUE | CA10: =IF(tblemployee[[#This Row],[Attrition]]="Yes",1,0) -> 0 | CB10: =IF(tblemployee[[#This Row],[OverTime]]="Yes",1,0) -> 0
A11: 36 | B11: No | C11: Travel_Rarely | D11: 1299 | E11: Research & Development | F11: 27 | G11: {=_xlfn.IFS( F11 <= 10, "Near", F11 <= 20, "Far", TRUE, "Very Far")} -> Very Far | H11: 3 | I11: =_xlfn.XLOOKUP(H11,Lookup!C:C,Lookup!D:D) -> Bachelor | J11: Medical | K11: 1 | L11: 13 | M11: 3 | N11: =_xlfn.XLOOKUP(M11,Lookup!E:E,Lookup!F:F) -> High | O11: Male | P11: 94 | Q11: 3 | R11: =_xlfn.XLOOKUP(Q11,Lookup!G:G,Lookup!H:H) -> High | S11: 2 | T11: =_xlfn.XLOOKUP(S11,Lookup!A:A,Lookup!B:B) -> Junior | U11: Healthcare Representative | V11: 3 | W11: =_xlfn.XLOOKUP(V11,Lookup!I:I,Lookup!J:J) -> High | X11: Married | Y11: 5237 | Z11: {=_xlfn.IFS(Y11<3000,"Low",Y11<7000,"Medium",TRUE,"High")} -> Medium | AA11: 16577 | AB11: 6 | AC11: Y | AD11: No | AE11: 13 | AF11: 3 | AG11: =_xlfn.XLOOKUP(AF11,Lookup!K:K,Lookup!L:L) -> Meet Expect | AH11: 2 | AI11: =LOOKUP(AH11,Lookup!M:M,Lookup!N:N) -> Medium | AJ11: 80 | AK11: 2 | AL11: =_xlfn.XLOOKUP(AK11,Lookup!O:O,Lookup!P:P) -> Medium | AM11: 17 | AN11: {=_xlfn.IFS( AM11<=5,"0-5", AM11<=10,"6-10", AM11<=20,"11-20", TRUE,"20+")} -> 11-20 | AO11: 3 | AP11: 2 | AQ11: =_xlfn.XLOOKUP(AP11,Lookup!Q:Q,Lookup!R:R) -> Good | AR11: 7 | AS11: {=_xlfn.IFS( AR11 <=1,"New Employee", AR11 <=3, "Early Career", AR11 <=7, "Experienced", TRUE, "Veteran")} -> Experienced | AT11: 7 | AU11: 7 | AV11: {=_xlfn.IFS( AU11=0,"Recently Promoted", AU11<=3, "Normal", TRUE, "Long Time No Promotion")} -> Long Time No Promotion | AW11: 7 | AX11: =IF(COUNTIF(L11:$L$1471,L11)>1,1,0) -> 0 | BA11: =IF(AZ11=X11,1,0) -> 0 | BC11: =IF(U11=BB11,1,0) -> 0 | BE11: =IF(BD11=J11,1,0) -> 0 | BG11: =IF(BF11=E11,1,0) -> 0 | BI11: =IF(C11=BH11,1,0) -> 0 | BR11: {=_xlfn.IFS( A11<=25,"18-25", A11<=35,"26-35", A11<=45,"36-45", A11<=59,"46-59", TRUE,"60+")} -> 36-45 | BX11: =AND(ISNUMBER(A11),ISNUMBER(D11),ISNUMBER(A11),ISNUMBER(F11),ISNUMBER(H11),ISNUMBER(K11),ISNUMBER(L11),ISNUMBER(M11),ISNUMBER(P11),ISNUMBER(Q11),ISNUMBER(S11),ISNUMBER(V11),ISNUMBER(Y11),ISNUMBER(AA11),ISNUMBER(AB11)) -> TRUE | BY11: =AND(ISNUMBER(A11),ISNUMBER(D11),ISNUMBER(A11),ISNUMBER(F11),ISNUMBER(H11),ISNUMBER(K11),ISNUMBER(L11),ISNUMBER(M11),ISNUMBER(P11),ISNUMBER(Q11),ISNUMBER(S11),ISNUMBER(V11),ISNUMBER(Y11),ISNUMBER(AA11),ISNUMBER(AB11))>0 -> TRUE | BZ11: =COUNT(AE11:AW11)>0 -> TRUE | CA11: =IF(tblemployee[[#This Row],[Attrition]]="Yes",1,0) -> 0 | CB11: =IF(tblemployee[[#This Row],[OverTime]]="Yes",1,0) -> 0
A12: 35 | B12: No | C12: Travel_Rarely | D12: 809 | E12: Research & Development | F12: 16 | G12: {=_xlfn.IFS( F12 <= 10, "Near", F12 <= 20, "Far", TRUE, "Very Far")} -> Far | H12: 3 | I12: =_xlfn.XLOOKUP(H12,Lookup!C:C,Lookup!D:D) -> Bachelor | J12: Medical | K12: 1 | L12: 14 | M12: 1 | N12: =_xlfn.XLOOKUP(M12,Lookup!E:E,Lookup!F:F) -> Low | O12: Male | P12: 84 | Q12: 4 | R12: =_xlfn.XLOOKUP(Q12,Lookup!G:G,Lookup!H:H) -> Very High | S12: 1 | T12: =_xlfn.XLOOKUP(S12,Lookup!A:A,Lookup!B:B) -> Entry Level | U12: Laboratory Technician | V12: 2 | W12: =_xlfn.XLOOKUP(V12,Lookup!I:I,Lookup!J:J) -> Medium | X12: Married | Y12: 2426 | Z12: {=_xlfn.IFS(Y12<3000,"Low",Y12<7000,"Medium",TRUE,"High")} -> Low | AA12: 16479 | AB12: 0 | AC12: Y | AD12: No | AE12: 13 | AF12: 3 | AG12: =_xlfn.XLOOKUP(AF12,Lookup!K:K,Lookup!L:L) -> Meet Expect | AH12: 3 | AI12: =LOOKUP(AH12,Lookup!M:M,Lookup!N:N) -> High | AJ12: 80 | AK12: 1 | AL12: =_xlfn.XLOOKUP(AK12,Lookup!O:O,Lookup!P:P) -> Basic | AM12: 6 | AN12: {=_xlfn.IFS( AM12<=5,"0-5", AM12<=10,"6-10", AM12<=20,"11-20", TRUE,"20+")} -> 6-10 | AO12: 5 | AP12: 3 | AQ12: =_xlfn.XLOOKUP(AP12,Lookup!Q:Q,Lookup!R:R) -> Better | AR12: 5 | AS12: {=_xlfn.IFS( AR12 <=1,"New Employee", AR12 <=3, "Early Career", AR12 <=7, "Experienced", TRUE, "Veteran")} -> Experienced | AT12: 4 | AU12: 0 | AV12: {=_xlfn.IFS( AU12=0,"Recently Promoted", AU12<=3, "Normal", TRUE, "Long Time No Promotion")} -> Recently Promoted | AW12: 3 | AX12: =IF(COUNTIF(L12:$L$1471,L12)>1,1,0) -> 0 | BA12: =IF(AZ12=X12,1,0) -> 0 | BC12: =IF(U12=BB12,1,0) -> 0 | BE12: =IF(BD12=J12,1,0) -> 0 | BG12: =IF(BF12=E12,1,0) -> 0 | BI12: =IF(C12=BH12,1,0) -> 0 | BR12: {=_xlfn.IFS( A12<=25,"18-25", A12<=35,"26-35", A12<=45,"36-45", A12<=59,"46-59", TRUE,"60+")} -> 26-35 | BX12: =AND(ISNUMBER(A12),ISNUMBER(D12),ISNUMBER(A12),ISNUMBER(F12),ISNUMBER(H12),ISNUMBER(K12),ISNUMBER(L12),ISNUMBER(M12),ISNUMBER(P12),ISNUMBER(Q12),ISNUMBER(S12),ISNUMBER(V12),ISNUMBER(Y12),ISNUMBER(AA12),ISNUMBER(AB12)) -> TRUE | BY12: =AND(ISNUMBER(A12),ISNUMBER(D12),ISNUMBER(A12),ISNUMBER(F12),ISNUMBER(H12),ISNUMBER(K12),ISNUMBER(L12),ISNUMBER(M12),ISNUMBER(P12),ISNUMBER(Q12),ISNUMBER(S12),ISNUMBER(V12),ISNUMBER(Y12),ISNUMBER(AA12),ISNUMBER(AB12))>0 -> TRUE | BZ12: =COUNT(AE12:AW12)>0 -> TRUE | CA12: =IF(tblemployee[[#This Row],[Attrition]]="Yes",1,0) -> 0 | CB12: =IF(tblemployee[[#This Row],[OverTime]]="Yes",1,0) -> 0
A13: 29 | B13: No | C13: Travel_Rarely | D13: 153 | E13: Research & Development | F13: 15 | G13: {=_xlfn.IFS( F13 <= 10, "Near", F13 <= 20, "Far", TRUE, "Very Far")} -> Far | H13: 2 | I13: =_xlfn.XLOOKUP(H13,Lookup!C:C,Lookup!D:D) -> College | J13: Life Sciences | K13: 1 | L13: 15 | M13: 4 | N13: =_xlfn.XLOOKUP(M13,Lookup!E:E,Lookup!F:F) -> Very High | O13: Female | P13: 49 | Q13: 2 | R13: =_xlfn.XLOOKUP(Q13,Lookup!G:G,Lookup!H:H) -> Medium | S13: 2 | T13: =_xlfn.XLOOKUP(S13,Lookup!A:A,Lookup!B:B) -> Junior | U13: Laboratory Technician | V13: 3 | W13: =_xlfn.XLOOKUP(V13,Lookup!I:I,Lookup!J:J) -> High | X13: Single | Y13: 4193 | Z13: {=_xlfn.IFS(Y13<3000,"Low",Y13<7000,"Medium",TRUE,"High")} -> Medium | AA13: 12682 | AB13: 0 | AC13: Y | AD13: Yes | AE13: 12 | AF13: 3 | AG13: =_xlfn.XLOOKUP(AF13,Lookup!K:K,Lookup!L:L) -> Meet Expect | AH13: 4 | AI13: =LOOKUP(AH13,Lookup!M:M,Lookup!N:N) -> Very High | AJ13: 80 | AK13: 0 | AL13: =_xlfn.XLOOKUP(AK13,Lookup!O:O,Lookup!P:P) -> None | AM13: 10 | AN13: {=_xlfn.IFS( AM13<=5,"0-5", AM13<=10,"6-10", AM13<=20,"11-20", TRUE,"20+")} -> 6-10 | AO13: 3 | AP13: 3 | AQ13: =_xlfn.XLOOKUP(AP13,Lookup!Q:Q,Lookup!R:R) -> Better | AR13: 9 | AS13: {=_xlfn.IFS( AR13 <=1,"New Employee", AR13 <=3, "Early Career", AR13 <=7, "Experienced", TRUE, "Veteran")} -> Veteran | AT13: 5 | AU13: 0 | AV13: {=_xlfn.IFS( AU13=0,"Recently Promoted", AU13<=3, "Normal", TRUE, "Long Time No Promotion")} -> Recently Promoted | AW13: 8 | AX13: =IF(COUNTIF(L13:$L$1471,L13)>1,1,0) -> 0 | BA13: =IF(AZ13=X13,1,0) -> 0 | BC13: =IF(U13=BB13,1,0) -> 0 | BE13: =IF(BD13=J13,1,0) -> 0 | BG13: =IF(BF13=E13,1,0) -> 0 | BI13: =IF(C13=BH13,1,0) -> 0 | BR13: {=_xlfn.IFS( A13<=25,"18-25", A13<=35,"26-35", A13<=45,"36-45", A13<=59,"46-59", TRUE,"60+")} -> 26-35 | BX13: =AND(ISNUMBER(A13),ISNUMBER(D13),ISNUMBER(A13),ISNUMBER(F13),ISNUMBER(H13),ISNUMBER(K13),ISNUMBER(L13),ISNUMBER(M13),ISNUMBER(P13),ISNUMBER(Q13),ISNUMBER(S13),ISNUMBER(V13),ISNUMBER(Y13),ISNUMBER(AA13),ISNUMBER(AB13)) -> TRUE | BY13: =AND(ISNUMBER(A13),ISNUMBER(D13),ISNUMBER(A13),ISNUMBER(F13),ISNUMBER(H13),ISNUMBER(K13),ISNUMBER(L13),ISNUMBER(M13),ISNUMBER(P13),ISNUMBER(Q13),ISNUMBER(S13),ISNUMBER(V13),ISNUMBER(Y13),ISNUMBER(AA13),ISNUMBER(AB13))>0 -> TRUE | BZ13: =COUNT(AE13:AW13)>0 -> TRUE | CA13: =IF(tblemployee[[#This Row],[Attrition]]="Yes",1,0) -> 0 | CB13: =IF(tblemployee[[#This Row],[OverTime]]="Yes",1,0) -> 1
A14: 31 | B14: No | C14: Travel_Rarely | D14: 670 | E14: Research & Development | F14: 26 | G14: {=_xlfn.IFS( F14 <= 10, "Near", F14 <= 20, "Far", TRUE, "Very Far")} -> Very Far | H14: 1 | I14: =_xlfn.XLOOKUP(H14,Lookup!C:C,Lookup!D:D) -> Below College | J14: Life Sciences | K14: 1 | L14: 16 | M14: 1 | N14: =_xlfn.XLOOKUP(M14,Lookup!E:E,Lookup!F:F) -> Low | O14: Male | P14: 31 | Q14: 3 | R14: =_xlfn.XLOOKUP(Q14,Lookup!G:G,Lookup!H:H) -> High | S14: 1 | T14: =_xlfn.XLOOKUP(S14,Lookup!A:A,Lookup!B:B) -> Entry Level | U14: Research Scientist | V14: 3 | W14: =_xlfn.XLOOKUP(V14,Lookup!I:I,Lookup!J:J) -> High | X14: Divorced | Y14: 2911 | Z14: {=_xlfn.IFS(Y14<3000,"Low",Y14<7000,"Medium",TRUE,"High")} -> Low | AA14: 15170 | AB14: 1 | AC14: Y | AD14: No | AE14: 17 | AF14: 3 | AG14: =_xlfn.XLOOKUP(AF14,Lookup!K:K,Lookup!L:L) -> Meet Expect | AH14: 4 | AI14: =LOOKUP(AH14,Lookup!M:M,Lookup!N:N) -> Very High | AJ14: 80 | AK14: 1 | AL14: =_xlfn.XLOOKUP(AK14,Lookup!O:O,Lookup!P:P) -> Basic | AM14: 5 | AN14: {=_xlfn.IFS( AM14<=5,"0-5", AM14<=10,"6-10", AM14<=20,"11-20", TRUE,"20+")} -> 0-5 | AO14: 1 | AP14: 2 | AQ14: =_xlfn.XLOOKUP(AP14,Lookup!Q:Q,Lookup!R:R) -> Good | AR14: 5 | AS14: {=_xlfn.IFS( AR14 <=1,"New Employee", AR14 <=3, "Early Career", AR14 <=7, "Experienced", TRUE, "Veteran")} -> Experienced | AT14: 2 | AU14: 4 | AV14: {=_xlfn.IFS( AU14=0,"Recently Promoted", AU14<=3, "Normal", TRUE, "Long Time No Promotion")} -> Long Time No Promotion | AW14: 3 | AX14: =IF(COUNTIF(L14:$L$1471,L14)>1,1,0) -> 0 | BA14: =IF(AZ14=X14,1,0) -> 0 | BC14: =IF(U14=BB14,1,0) -> 0 | BE14: =IF(BD14=J14,1,0) -> 0 | BG14: =IF(BF14=E14,1,0) -> 0 | BI14: =IF(C14=BH14,1,0) -> 0 | BR14: {=_xlfn.IFS( A14<=25,"18-25", A14<=35,"26-35", A14<=45,"36-45", A14<=59,"46-59", TRUE,"60+")} -> 26-35 | BX14: =AND(ISNUMBER(A14),ISNUMBER(D14),ISNUMBER(A14),ISNUMBER(F14),ISNUMBER(H14),ISNUMBER(K14),ISNUMBER(L14),ISNUMBER(M14),ISNUMBER(P14),ISNUMBER(Q14),ISNUMBER(S14),ISNUMBER(V14),ISNUMBER(Y14),ISNUMBER(AA14),ISNUMBER(AB14)) -> TRUE | BY14: =AND(ISNUMBER(A14),ISNUMBER(D14),ISNUMBER(A14),ISNUMBER(F14),ISNUMBER(H14),ISNUMBER(K14),ISNUMBER(L14),ISNUMBER(M14),ISNUMBER(P14),ISNUMBER(Q14),ISNUMBER(S14),ISNUMBER(V14),ISNUMBER(Y14),ISNUMBER(AA14),ISNUMBER(AB14))>0 -> TRUE | BZ14: =COUNT(AE14:AW14)>0 -> TRUE | CA14: =IF(tblemployee[[#This Row],[Attrition]]="Yes",1,0) -> 0 | CB14: =IF(tblemployee[[#This Row],[OverTime]]="Yes",1,0) -> 0
A15: 34 | B15: No | C15: Travel_Rarely | D15: 1346 | E15: Research & Development | F15: 19 | G15: {=_xlfn.IFS( F15 <= 10, "Near", F15 <= 20, "Far", TRUE, "Very Far")} -> Far | H15: 2 | I15: =_xlfn.XLOOKUP(H15,Lookup!C:C,Lookup!D:D) -> College | J15: Medical | K15: 1 | L15: 18 | M15: 2 | N15: =_xlfn.XLOOKUP(M15,Lookup!E:E,Lookup!F:F) -> Medium | O15: Male | P15: 93 | Q15: 3 | R15: =_xlfn.XLOOKUP(Q15,Lookup!G:G,Lookup!H:H) -> High | S15: 1 | T15: =_xlfn.XLOOKUP(S15,Lookup!A:A,Lookup!B:B) -> Entry Level | U15: Laboratory Technician | V15: 4 | W15: =_xlfn.XLOOKUP(V15,Lookup!I:I,Lookup!J:J) -> Very High | X15: Divorced | Y15: 2661 | Z15: {=_xlfn.IFS(Y15<3000,"Low",Y15<7000,"Medium",TRUE,"High")} -> Low | AA15: 8758 | AB15: 0 | AC15: Y | AD15: No | AE15: 11 | AF15: 3 | AG15: =_xlfn.XLOOKUP(AF15,Lookup!K:K,Lookup!L:L) -> Meet Expect | AH15: 3 | AI15: =LOOKUP(AH15,Lookup!M:M,Lookup!N:N) -> High | AJ15: 80 | AK15: 1 | AL15: =_xlfn.XLOOKUP(AK15,Lookup!O:O,Lookup!P:P) -> Basic | AM15: 3 | AN15: {=_xlfn.IFS( AM15<=5,"0-5", AM15<=10,"6-10", AM15<=20,"11-20", TRUE,"20+")} -> 0-5 | AO15: 2 | AP15: 3 | AQ15: =_xlfn.XLOOKUP(AP15,Lookup!Q:Q,Lookup!R:R) -> Better | AR15: 2 | AS15: {=_xlfn.IFS( AR15 <=1,"New Employee", AR15 <=3, "Early Career", AR15 <=7, "Experienced", TRUE, "Veteran")} -> Early Career | AT15: 2 | AU15: 1 | AV15: {=_xlfn.IFS( AU15=0,"Recently Promoted", AU15<=3, "Normal", TRUE, "Long Time No Promotion")} -> Normal | AW15: 2 | AX15: =IF(COUNTIF(L15:$L$1471,L15)>1,1,0) -> 0 | BA15: =IF(AZ15=X15,1,0) -> 0 | BC15: =IF(U15=BB15,1,0) -> 0 | BE15: =IF(BD15=J15,1,0) -> 0 | BG15: =IF(BF15=E15,1,0) -> 0 | BI15: =IF(C15=BH15,1,0) -> 0 | BR15: {=_xlfn.IFS( A15<=25,"18-25", A15<=35,"26-35", A15<=45,"36-45", A15<=59,"46-59", TRUE,"60+")} -> 26-35 | BX15: =AND(ISNUMBER(A15),ISNUMBER(D15),ISNUMBER(A15),ISNUMBER(F15),ISNUMBER(H15),ISNUMBER(K15),ISNUMBER(L15),ISNUMBER(M15),ISNUMBER(P15),ISNUMBER(Q15),ISNUMBER(S15),ISNUMBER(V15),ISNUMBER(Y15),ISNUMBER(AA15),ISNUMBER(AB15)) -> TRUE | BY15: =AND(ISNUMBER(A15),ISNUMBER(D15),ISNUMBER(A15),ISNUMBER(F15),ISNUMBER(H15),ISNUMBER(K15),ISNUMBER(L15),ISNUMBER(M15),ISNUMBER(P15),ISNUMBER(Q15),ISNUMBER(S15),ISNUMBER(V15),ISNUMBER(Y15),ISNUMBER(AA15),ISNUMBER(AB15))>0 -> TRUE | BZ15: =COUNT(AE15:AW15)>0 -> TRUE | CA15: =IF(tblemployee[[#This Row],[Attrition]]="Yes",1,0) -> 0 | CB15: =IF(tblemployee[[#This Row],[OverTime]]="Yes",1,0) -> 0
... A1471: 34 | B1471: No | C1471: Travel_Rarely | D1471: 628 | E1471: Research & Development | F1471: 8 | G1471: {=_xlfn.IFS( F1471 <= 10, "Near", F1471 <= 20, "Far", TRUE, "Very Far")} -> Near | H1471: 3 | I1471: =_xlfn.XLOOKUP(H1471,Lookup!C:C,Lookup!D:D) -> Bachelor | J1471: Medical | K1471: 1 | L1471: 2068 | M1471: 2 | N1471: =_xlfn.XLOOKUP(M1471,Lookup!E:E,Lookup!F:F) -> Medium | O1471: Male | P1471: 82 | Q1471: 4 | R1471: =_xlfn.XLOOKUP(Q1471,Lookup!G:G,Lookup!H:H) -> Very High | S1471: 2 | T1471: =_xlfn.XLOOKUP(S1471,Lookup!A:A,Lookup!B:B) -> Junior | U1471: Laboratory Technician | V1471: 3 | W1471: =_xlfn.XLOOKUP(V1471,Lookup!I:I,Lookup!J:J) -> High | X1471: Married | Y1471: 4404 | Z1471: {=_xlfn.IFS(Y1471<3000,"Low",Y1471<7000,"Medium",TRUE,"High")} -> Medium | AA1471: 10228 | AB1471: 2 | AC1471: Y | AD1471: No | AE1471: 12 | AF1471: 3 | AG1471: =_xlfn.XLOOKUP(AF1471,Lookup!K:K,Lookup!L:L) -> Meet Expect | AH1471: 1 | AI1471: =LOOKUP(AH1471,Lookup!M:M,Lookup!N:N) -> Low | AJ1471: 80 | AK1471: 0 | AL1471: =_xlfn.XLOOKUP(AK1471,Lookup!O:O,Lookup!P:P) -> None | AM1471: 6 | AN1471: {=_xlfn.IFS( AM1471<=5,"0-5", AM1471<=10,"6-10", AM1471<=20,"11-20", TRUE,"20+")} -> 6-10 | AO1471: 3 | AP1471: 4 | AQ1471: =_xlfn.XLOOKUP(AP1471,Lookup!Q:Q,Lookup!R:R) -> Best | AR1471: 4 | AS1471: {=_xlfn.IFS( AR1471 <=1,"New Employee", AR1471 <=3, "Early Career", AR1471 <=7, "Experienced", TRUE, "Veteran")} -> Experienced | AT1471: 3 | AU1471: 1 | AV1471: {=_xlfn.IFS( AU1471=0,"Recently Promoted", AU1471<=3, "Normal", TRUE, "Long Time No Promotion")} -> Normal | AW1471: 2 | AX1471: =IF(COUNTIF(L1471:$L$1471,L1471)>1,1,0) -> 0 | BA1471: =IF(AZ1471=X1471,1,0) -> 0 | BC1471: =IF(U1471=BB1471,1,0) -> 0 | BE1471: =IF(BD1471=J1471,1,0) -> 0 | BG1471: =IF(BF1471=E1471,1,0) -> 0 | BI1471: =IF(C1471=BH1471,1,0) -> 0 | BR1471: {=_xlfn.IFS( A1471<=25,"18-25", A1471<=35,"26-35", A1471<=45,"36-45", A1471<=59,"46-59", TRUE,"60+")} -> 26-35 | BX1471: =AND(ISNUMBER(A1471),ISNUMBER(D1471),ISNUMBER(A1471),ISNUMBER(F1471),ISNUMBER(H1471),ISNUMBER(K1471),ISNUMBER(L1471),ISNUMBER(M1471),ISNUMBER(P1471),ISNUMBER(Q1471),ISNUMBER(S1471),ISNUMBER(V1471),ISNUMBER(Y1471),ISNUMBER(AA1471),ISNUMBER(AB1471)) -> TRUE | BY1471: =AND(ISNUMBER(A1471),ISNUMBER(D1471),ISNUMBER(A1471),ISNUMBER(F1471),ISNUMBER(H1471),ISNUMBER(K1471),ISNUMBER(L1471),ISNUMBER(M1471),ISNUMBER(P1471),ISNUMBER(Q1471),ISNUMBER(S1471),ISNUMBER(V1471),ISNUMBER(Y1471),ISNUMBER(AA1471),ISNUMBER(AB1471))>0 -> TRUE | BZ1471: =COUNT(AE1471:AW1471)>0 -> TRUE | CA1471: =IF(tblemployee[[#This Row],[Attrition]]="Yes",1,0) -> 0 | CB1471: =IF(tblemployee[[#This Row],[OverTime]]="Yes",1,0) -> 0

Sheet Pivot
B2: Business Question 1 : Does working overtime increase employee attrition? | L2: Are dissatisfied employees leaving?
C3: Attrition | L3: Job Satisfaction | M3: Average of Attrition
C4: No | E4: Yes | G4: Total Employees | H4: Total % | L4: Low | M4: 0.2283737
B5: Overtime | C5: Employees | D5: % | E5: Employees | F5: % | L5: High | M5: 0.16515837
B6: No | C6: 944 | D6: 0.89563567 | E6: 110 | F6: 0.10436433 | G6: 1054 | H6: 1 | L6: Medium | M6: 0.16428571
B7: Yes | C7: 289 | D7: 0.69471154 | E7: 127 | F7: 0.30528846 | G7: 416 | H7: 1 | L7: Very High | M7: 0.11328976
B8: Grand Total | C8: 1233 | D8: 0.83877551 | E8: 237 | F8: 0.16122449 | G8: 1470 | H8: 1 | L8: Grand Total | M8: 0.16122449
L9: Low job satisfaction clearly increase attrition.
B12: Insight: overtime may be associated with higher employee turnover.
B13: Among employees who work overtime, approximately 30% left the company,
B14: which is significantly higher than employees who do not work overtime.
B32: Work-life balance with atttrition | L32: Monthly Income with attrition
B33: Work-life balance | C33: Average of Attrition | L33: Monthly Income | M33: Average of Attrition
B34: Bad | C34: 0.3125 | L34: Low | M34: 0.28607595
B35: Best | C35: 0.17647059 | L35: Medium | M35: 0.1203125
B36: Good | C36: 0.16860465 | L36: High | M36: 0.10804598
B37: Better | C37: 0.14221725 | L37: Grand Total | M37: 0.16122449
B38: Grand Total | C38: 0.16122449
B54: Poor work-life balance is a major reason people leave. | L54: Employees with low salary are much more likely to leave.
B58: Environment Satisfaction with Attrition | L58: Promotion with attrition
B59: Environment Satisfaction | C59: Average of Attrition | L59: Promotion Status | M59: Average of Attrition
B60: Low | C60: 0.25352113 | L60: Recently Promoted | M60: 0.18932874
B61: Medium | C61: 0.14982578 | L61: Normal | M61: 0.14964789
B62: High | C62: 0.13686534 | L62: Long Time No Promotion | M62: 0.13084112
B63: Very High | C63: 0.13452915 | L63: Grand Total | M63: 0.16122449
B64: Grand Total | C64: 0.16122449
B81: Bad workplace environment increases attrition' | L81: 0 - 3 years newcomber quite the job more than senior.
B83: Conclusion: | L83: Average of YearsAtCompany
B84: The strongest driver of attrition is overtime, with employees working overtime leaving at nearly 3 times the rate of others. | L84: 7.0081633
B85: Work-life balance is another critical factor, suggesting that workload pressure is a key issue.
B86: Low salary and low job satisfaction further increase the likelihood of employees leaving.
B87: Additionally, poor workplace environment contributes to higher attrition.
B91: Attrition by Department | L91: Attrition by Job Role
B92: Department | C92: Average of Attrition | L92: Job Role | M92: Average of Attrition
B93: Sales | C93: 0.20627803 | L93: Sales Representative | M93: 0.39759036
B94: Human Resources | C94: 0.19047619 | L94: Laboratory Technician | M94: 0.23938224
B95: Research & Development | C95: 0.1383975 | L95: Human Resources | M95: 0.23076923
B96: Grand Total | C96: 0.16122449 | L96: Sales Executive | M96: 0.17484663
L97: Research Scientist | M97: 0.1609589
L98: Manufacturing Director | M98: 0.068965517
...

Sheet Dashboard
B1: IBM HR EMPLOYEE ATTRITION DASHBOARD
C3: Total Employees | D3: Total Attrition | E3: Average Year at Company | F3: Attrition Rate
C4: =GETPIVOTDATA("Employees",Pivot!$B$3) -> 1470 | D4: =GETPIVOTDATA("EmployeeNumber",Pivot!$B$3,"Attrition","Yes") -> 237 | E4: =GETPIVOTDATA("YearsAtCompany",Pivot!$L$83) -> 7.0081633 | F4: =D4/C4 -> 0.16122449
B7: OVERALL ATTRITION
B16: POSSIBLE REASONS
B17: OVERTIME VS ATTRITION
B26: MONTHLY INCOME WITH ATTRITION

Sheet Lookup
A1: JobLevel | B1: LevelName | C1: Code | D1: Meaning | E1: Env_Satis | F1: Name | G1: Job_Involvment | H1: Name | I1: Job_satis | J1: Name | K1: Performance_rating | L1: Perfor_Name | M1: Relationship_satis | O1: Stock_Option_lvl | Q1: WorkLB | R1: WLB_Name
A2: 1 | B2: Entry Level | C2: 1 | D2: Below College | E2: 1 | F2: Low | G2: 1 | H2: Low | I2: 1 | J2: Low | K2: 3 | L2: Meet Expect | M2: 1 | N2: Low | O2: 0 | P2: None | Q2: 1 | R2: Bad
A3: 2 | B3: Junior | C3: 2 | D3: College | E3: 2 | F3: Medium | G3: 2 | H3: Medium | I3: 2 | J3: Medium | K3: 4 | L3: Exceed Expect | M3: 2 | N3: Medium | O3: 1 | P3: Basic | Q3: 2 | R3: Good
A4: 3 | B4: Senior | C4: 3 | D4: Bachelor | E4: 3 | F4: High | G4: 3 | H4: High | I4: 3 | J4: High | M4: 3 | N4: High | O4: 2 | P4: Medium | Q4: 3 | R4: Better
A5: 4 | B5: Manager | C5: 4 | D5: Master | E5: 4 | F5: Very High | G5: 4 | H5: Very High | I5: 4 | J5: Very High | M5: 4 | N5: Very High | O5: 3 | P5: High | Q5: 4 | R5: Best
A6: 5 | B6: Director | C6: 5 | D6: Doctor

Sheet About Dataset
A1: About Dataset
A2: Uncover the factors that lead to employee attrition and explore important questions such as ‘show me a breakdown of distance from home by job role and attrition’ or ‘compare average monthly income by education and attrition’. This is a fictional data set created by IBM data scientists.
A3: Education | C3: Many beginners confuse:
A4: 1 'Below College'
A5: 2 'College' | C5: MonthlyIncome
A6: 3 'Bachelor'
A7: 4 'Master' | C7: with
A8: 5 'Doctor'
A9: EnvironmentSatisfaction | C9: MonthlyRate
A10: 1 'Low'
A11: 2 'Medium' | C11: They are NOT the same.
A12: 3 'High'
A13: 4 'Very High' | C13: MonthlyIncome
A14: JobInvolvement
A15: 1 'Low' | C15: {=actual salary} -> #NAME?
A16: 2 'Medium'
A17: 3 'High' | C17: MonthlyRate
A18: 4 'Very High'
A19: JobSatisfaction | C19: = payroll/internal monthly rate | F19: လုပ်ခလစာ/ပြည်တွင်းလစဉ်နှုန်းထား
A20: 1 'Low'
A21: 2 'Medium'
A22: 3 'High'
A23: 4 'Very High'
A24: PerformanceRating
A25: 1 'Low'
A26: 2 'Good'
A27: 3 'Excellent'
A28: 4 'Outstanding'
A29: RelationshipSatisfaction
A30: 1 'Low'
A31: 2 'Medium'
... A43: Do employees with low work-life balance leave more often?
